Workbook

Sheet Overview
A1: Development Workbook: <Interface Purpose> from <SOURCE SYSTEM> to <TARGET SYSTEM>
I11: Project ID: | L11: <PROJECT ID>
I13: Project Name: | L13: <PROJECT NAME>
I15: Interface ID: | L15: <DOCUMENT NAME>
E20: Project Members
E22: TSP | M22: <Customer>
E23: Project Manager | M23: Project Manager
E24: SAP SuccessFactors Platform | M24: SAP SuccessFactors Platform
E25: SAP SuccessFactors Employee Central | M25: SAP SuccessFactors Employee Central
E26: SAP SuccessFactors People Analytics | M26: SAP SuccessFactors People Analytics
E27: SAP SuccessFactors Onboarding 1.0 | M27: SAP SuccessFactors Onboarding 1.0
E28: SAP SuccessFactors Onboarding 2.0 | M28: SAP SuccessFactors Onboarding 2.0
E29: SAP SuccessFactors Learning Management System | M29: SAP SuccessFactors Learning Management System
E30: SAP SuccessFactors Workforce Analytics | M30: SAP SuccessFactors Workforce Analytics
E31: SAP SuccessFactors Recruiting Marketing | M31: SAP SuccessFactors Recruiting Marketing
E32: SAP SuccessFactors PM & GM | M32: SAP SuccessFactors PM & GM
E33: SAP IAS/IPS | M33: SAP IAS/IPS
... E42: SAP ABAP Developer | M42: SAP ABAP Developer
A46: DOCUMENTATION STATUS
A52: EXPLORE - DEV
B56: Interface Checklist | H56: Functional / Technical Specification | M56: Mapping Table | S56: Unit Testing
A63: PRE-UAT - QAS
B67: Interface Checklist | H67: Functional / Technical Specification | M67: Mapping Table | S67: Unit Testing
A75: DEPLOY - PROD
B79: Interface Checklist | H79: Functional / Technical Specification | M79: Mapping Table | S79: Unit Testing

Sheet EXPLORE - FS
A1: <INT ID - DESCRIPTION> Functional/Technical Specification
A3: Document Roles
C5: Role Name | D5: Consultant Name | E5: Create / Review
C6: SAP Integration Developer | D6: =IF(VLOOKUP(C6,Overview!$E$23:$J$42,5,FALSE)="","",VLOOKUP(C6,Overview!$E$23:$J$42,5,FALSE)) | E6: Create
C7: SAP SuccessFactors Platform | D7: =IF(VLOOKUP(C7,Overview!$E$23:$J$42,5,FALSE)="","",VLOOKUP(C7,Overview!$E$23:$J$42,5,FALSE)) | E7: Create
C8: SAP Solution Architect | D8: =IF(VLOOKUP(C8,Overview!$E$23:$J$42,5,FALSE)="","",VLOOKUP(C8,Overview!$E$23:$J$42,5,FALSE)) | E8: Review
C9: SAP Integration Architect | D9: =IF(VLOOKUP(C9,Overview!$E$23:$J$42,5,FALSE)="","",VLOOKUP(C9,Overview!$E$23:$J$42,5,FALSE)) | E9: Review | H9: *Do not edit
A11: Version History
B13: Description | C13: Stage | D13: Created By | E13: Creation Date | F13: Document Status | G13: Approved By | I13: Approval Date
C14: Dev Cycle 1 | F14: Initial
C15: Dev Cycle 2 | F15: Initial
C16: UAT | F16: Initial
A18: Overview
B20: <Insert a brief description about the development. Include the main objectives and goals and why this is required by the customer>
A26: Assumptions
B28: <List All the assumptions required to start the development> - <X data already exists in the system; X process is already configured>
A34: Dependencies
B36: <List all the dependencies with other developments, add the document ID or path if need it> - <X development is already done; X configuration must be done>
A42: Process Flow
A50: Process Description
B52: <Give an functional explanation (like a Story Telling) about the entire process requirement from Source to Middleware and then to Target to help the developer to understand the scenario. > <In case the process does not require integration, include the information only on the <Source System> and for <Middleware System> and <Target System>, inform N/A. Once upon a time…. <Source System> Process Details <Add details about the SOURCE SYSTEM process inserted in the previous section > The process starts…. <Middleware System> Process Details <Add details about the MIDDLEWARE process inserted in the previous section > <Insert details about Filters, Tables to read, Full transmission start dates> The data sent by Source System… <Target System> Process Details <Add details about the TARGET SYSTEM process inserted in the previous section > After receiving the data….
A57: Monitoring Strategy
A64: Error Handling
A71: Mapping Logic (Summary)
A82: Connectivity Settings
A101: Technical User x System
E103: DEV | G103: QAS | I103: PROD
E104: User | G104: User | I104: User
B105: SAP BTP
B106: SAP Integration Suite
B107: SAP Extension Suite
B108: SAP Cloud Connector
B109: SAP IAS
B110: SAP IPS
B111: SAP HR OnPremise
B112: SAP ECP
B113: SAP S/4 HANA or ECC
B114: SAP C4/C
B115: SF BizX
B116: SF LMS
...

Sheet EXPLORE - Mapping
B2: Document Roles
D4: Role Name | E4: Consultant Name | F4: Create / Review
D5: SAP Integration Developer | E5: =IF(VLOOKUP(D5,Overview!$E$23:$J$42,5,FALSE)="","",VLOOKUP(D5,Overview!$E$23:$J$42,5,FALSE)) | F5: Create
D6: SAP SuccessFactors Platform | E6: =IF(VLOOKUP(D6,Overview!$E$23:$J$42,5,FALSE)="","",VLOOKUP(D6,Overview!$E$23:$J$42,5,FALSE)) | F6: Create
D7: SAP Solution Architect | E7: =IF(VLOOKUP(D7,Overview!$E$23:$J$42,5,FALSE)="","",VLOOKUP(D7,Overview!$E$23:$J$42,5,FALSE)) | F7: Review
D8: SAP Integration Architect | E8: =IF(VLOOKUP(D8,Overview!$E$23:$J$42,5,FALSE)="","",VLOOKUP(D8,Overview!$E$23:$J$42,5,FALSE)) | F8: Review | I8: *Do not edit
B10: Document Status
C12: Description | D12: Stage | E12: Created By | F12: Creation Date | G12: Document Status | H12: Approved By | J12: Approval Date
D13: DEV | G13: Initial
D14: QAS | G14: Initial
D15: PRD | G15: Initial
B17: Field Mappings
C19: <SOURCE SYSTEM> | F19: <TARGET SYSTEM> | K19: Country Specific Mapping | L19: Transformation Rules / Comments / Others
C20: Portlet / Table | D20: System Field ID | E20: Label | F20: Portlet / Table | G20: System Field ID | H20: Label | I20: Mandatory? | J20: Code Value Mapping

Sheet EXPLORE - Value Mappings
B1: Value Mappings: <Interface Purpose> from <SOURCE SYSTEM> to <TARGET SYSTEM>
B2: Document Roles
D4: Role Name | E4: Consultant Name | F4: Create / Review
D5: SAP Integration Developer | E5: =IF(VLOOKUP(D5,Overview!$E$23:$J$42,5,FALSE)="","",VLOOKUP(D5,Overview!$E$23:$J$42,5,FALSE)) | F5: Create
D6: SAP SuccessFactors Platform | E6: =IF(VLOOKUP(D6,Overview!$E$23:$J$42,5,FALSE)="","",VLOOKUP(D6,Overview!$E$23:$J$42,5,FALSE)) | F6: Create
D7: SAP Solution Architect | E7: =IF(VLOOKUP(D7,Overview!$E$23:$J$42,5,FALSE)="","",VLOOKUP(D7,Overview!$E$23:$J$42,5,FALSE)) | F7: Review
D8: SAP Integration Architect | E8: =IF(VLOOKUP(D8,Overview!$E$23:$J$42,5,FALSE)="","",VLOOKUP(D8,Overview!$E$23:$J$42,5,FALSE)) | F8: Review | I8: *Do not edit
B10: Document Status
C12: Description | D12: Stage | E12: Created By | F12: Creation Date | G12: Document Status | H12: Approved By | J12: Approval Date
D13: DEV | G13: Initial
D14: QAS | G14: Initial
D15: PRD | G15: Initial
B17: Value Mapping
B19: Field | C19: Source Value | D19: Target Value
B20: Gender | C20: M | D20: 1
B21: Gender | C21: F | D21: 2

Sheet EXPLORE - Test Scenarios
B1: Unit Testing Document: Testing Inventory
B2: Document Roles
C4: Role Name | D4: Consultant Name | E4: Create / Review
C5: SAP SuccessFactors Platform | D5: =IF(VLOOKUP(C5,Overview!$E$23:$J$42,5,FALSE)="","",VLOOKUP(C5,Overview!$E$23:$J$42,5,FALSE)) | E5: Create
C6: SAP Integration Developer | D6: =IF(VLOOKUP(C6,Overview!$E$23:$J$42,5,FALSE)="","",VLOOKUP(C6,Overview!$E$23:$J$42,5,FALSE)) | E6: Review
C7: SAP Solution Architect | D7: =IF(VLOOKUP(C7,Overview!$E$23:$J$42,5,FALSE)="","",VLOOKUP(C7,Overview!$E$23:$J$42,5,FALSE)) | E7: Review
C8: SAP Integration Architect | D8: =IF(VLOOKUP(C8,Overview!$E$23:$J$42,5,FALSE)="","",VLOOKUP(C8,Overview!$E$23:$J$42,5,FALSE)) | E8: Review | I8: *Do not edit
B10: Document Status
C12: Description | D12: Stage | E12: Created By | F12: Creation Date | G12: Document Status | H12: Approved By | J12: Approval Date
D13: DEV | G13: Initial
D14: QAS | G14: Initial
D15: PRD | G15: Initial
B17: Testing Scenarios
B19: ID | C19: Scenario | D19: Test Case | E19: Responsible | F19: Expected Results | G19: Technical Testing (x) | H19: Functional Testing (x) | I19: UAT Testing (x)

Sheet REALIZE - Interface Checklist
B1: Interface Checklist
B2: Document Roles
C4: Role Name | D4: Consultant Name | E4: Create / Review
C5: SAP Integration Developer | D5: =IF(VLOOKUP(C5,Overview!$E$23:$J$42,5,FALSE)="","",VLOOKUP(C5,Overview!$E$23:$J$42,5,FALSE)) | E5: Create
C6: SAP Integration Architect | D6: =IF(VLOOKUP(C6,Overview!$E$23:$J$42,5,FALSE)="","",VLOOKUP(C6,Overview!$E$23:$J$42,5,FALSE)) | E6: Review
H7: *Do not edit
B9: Document Status
C11: Description | D11: Stage | E11: Created By | F11: Creation Date | G11: Document Status | H11: Approved By | J11: Approval Date
D12: DEV | G12: Initial
D13: QAS | G13: Initial
D14: PRD | G14: Initial
B16: Interface Checklist
B18: <REMOVE THIS ROW> Interface Checklist contains all the TSP Guidelines that must be matched to deliver High Quality Developments. Please review this list before starting the development and complete it after the development making sure all the TSP Guidelines are successfully developed.
B19: Topic | C19: Subtopic | D19: Required | E19: Notes | F19: Compliant (Y/N)
B22: >>> Specification Checklist
B23: Definitions | C23: Data mappings are completed and clear | D23: Yes
B24: Definitions | C24: Value Mappings are completed and clear | D24: Yes
B25: Definitions | C25: APIs to be used are specified and ready to be used | D25: Yes
B26: Strategies | C26: Monitoring Strategy is designed | D26: Yes
B27: Strategies | C27: Reprocess Strategy is designed | D27: Yes
B28: Testing | C28: Testing scenarios provided | D28: Yes
B29: >>> Connectivity and Access Checklist
B30: Access | C30: Sender Access is Ready | D30: Yes
B31: Access | C31: Receivers Accesses are Ready | D31: Yes
B32: Access | C32: Middleware Access is Ready | D32: Yes
B33: Access | C33: SMTP Access is Ready | D33: Yes
B34: Connectivity | C34: Sender Connectivity check is OK | D34: Yes
B35: Connectivity | C35: Receiver Connectivity check is OK | D35: Yes
B36: Connectivity | C36: SMTP Connectivity check is OK | D36: Yes
B37: Connectivity | C37: Cloud Connector is ready | D37: Yes
B38: >>> Development Checklist
B39: General | C39: Interface pulling data using Last Modified Date/Time and employees to be reprocessed | D39: Yes
B40: General | C40: Interface working with Full Replication (all customer's employees) | D40: Yes
B41: General | C41: Documentation was added to Package Properties | D41: Yes
B42: General | C42: 10 Steps maximum per Integration Process | D42: Yes
B43: API Utilization | C43: Interface working with Full Replication (all customer's employees) | D43: Yes
B44: API Utilization | C44: Documentation was added to Package Properties | D44: Yes
B45: API Pagination | C45: 10 Steps maximum per Integration Process | D45: Yes
B46: API Pagination | C46: Target API Pagination implemented | D46: Yes
B47: Log Monitoring | C47: SuccessFactors Execution Manager | D47: Yes/No
...

Sheet REALIZE - CPI Details
A1: <INT ID - DESCRIPTION> Functional/Technical Specification
B3: Document Roles
C5: Role Name | D5: Consultant Name | E5: Create / Review
C6: SAP Integration Developer | D6: =IF(VLOOKUP(C6,Overview!$E$23:$J$42,5,FALSE)="","",VLOOKUP(C6,Overview!$E$23:$J$42,5,FALSE)) | E6: Create
C7: SAP Integration Architect | D7: =IF(VLOOKUP(C7,Overview!$E$23:$J$42,5,FALSE)="","",VLOOKUP(C7,Overview!$E$23:$J$42,5,FALSE)) | E7: Review | H7: *Do not edit
A9: Technical Objects
B11: <Complete the list with all the technical objects created / changed / enhanced during this development. Include Packages, Tables, Classes, Web Services, Cloud Integration Objects, etc.>
B12: No. | C12: Object Type | D12: Object Name | E12: Object Description | F12: Create /Change | G12: Package
A27: CPI Objects Description
B29: <List below all the Packages and iFlows created for the integration adding a brief description to each> - Package Name -- iFlow Name: Description
A35: <IFLOW> - Configuration Parameters
B37: <List all the parameters for the specific iFlow adding a brief description for each> - Parameter A: Desription - Parameter B: Description
A43: <IFLOW> - Configuration Parameters
B45: <List all the parameters for the specific iFlow adding a brief description for each> - Parameter A: Desription - Parameter B: Description
A51: <IFLOW> - Configuration Parameters
B53: <List all the parameters for the specific iFlow adding a brief description for each> - Parameter A: Desription - Parameter B: Description
A59: Jobs/Scheduler
B61: System (DEV/QA/PRD) | C61: Type (CPI/ABAP JOB/SCHEDULE SCRIPT) | E61: Job Name | G61: Frequency | I61: User | J61: Is Active (Yes/No)

Sheet REALIZE - ABAP Details
A1: <INT ID - DESCRIPTION> Functional/Technical Specification
A3: Document Roles
C5: Role Name | D5: Consultant Name | E5: Create / Review
C6: SAP Integration Developer | D6: =IF(VLOOKUP(C6,Overview!$E$23:$J$42,5,FALSE)="","",VLOOKUP(C6,Overview!$E$23:$J$42,5,FALSE)) | E6: Create
C7: SAP Integration Architect | D7: =IF(VLOOKUP(C7,Overview!$E$23:$J$42,5,FALSE)="","",VLOOKUP(C7,Overview!$E$23:$J$42,5,FALSE)) | E7: Review | H7: *Do not edit
A9: Technical Objects
B11: <Complete the list with all the technical objects created / changed / enhanced during this development. Include Packages, Tables, Classes, Web Services, Cloud Integration Objects, etc.>
B12: No. | C12: Object Type | D12: Object Name | E12: Object Description | F12: Create /Change | G12: Package
A27: ABAP Objects Created
B29: <List and briefly describe each ABAP Object created. Tables, Reports, Transactions, Table Views, Web services should be listed>
A35: <OBJECT> - Details
B37: <For the main objects, add all the details required to understand the development and the relationship between the main objects and the related ones>
A43: <OBJECT> - Details
B45: <For the main objects, add all the details required to understand the development and the relationship between the main objects and the related ones>
A51: <OBJECT> - Details
B53: <For the main objects, add all the details required to understand the development and the relationship between the main objects and the related ones>
A59: Soamanager Configurations
B61: <List and describe all the SOAMANAGER Required Configurations>
A67: Other Configurations
B69: <List and describe all other Required Configurations to be done in the SAP System>
A75: Jobs/Scheduler
B77: System (DEV/QA/PRD) | C77: Type (CPI/ABAP JOB/SCHEDULE SCRIPT) | E77: Job Name | G77: Frequency | I77: User | J77: Is Active (Yes/No)

Sheet REALIZE - Error Logs
A1: <INT ID - DESCRIPTION> Error Logs
B3: Error Log
B5: ID | C5: Error | D5: Description | F5: Process | G5: Responsible | H5: Status | I5: Comment | K5: Resolution

Sheet Technical Testing Results
B1: Unit Testing Document: Testing Inventory
B2: Document Roles
C4: Role Name | D4: Consultant Name | E4: Create / Review
C5: SAP Integration Developer | D5: =IF(VLOOKUP(C5,Overview!$E$23:$J$42,5,FALSE)="","",VLOOKUP(C5,Overview!$E$23:$J$42,5,FALSE)) | E5: Create
C6: SAP Solution Architect | D6: =IF(VLOOKUP(C6,Overview!$E$23:$J$42,5,FALSE)="","",VLOOKUP(C6,Overview!$E$23:$J$42,5,FALSE)) | E6: Review
C7: SAP Integration Architect | D7: =IF(VLOOKUP(C7,Overview!$E$23:$J$42,5,FALSE)="","",VLOOKUP(C7,Overview!$E$23:$J$42,5,FALSE)) | E7: Review
C8: SAP SuccessFactors Platform | D8: =IF(VLOOKUP(C8,Overview!$E$23:$J$42,5,FALSE)="","",VLOOKUP(C8,Overview!$E$23:$J$42,5,FALSE)) | E8: Review | I8: *Do not edit
B10: Document Status
C12: Description | D12: Stage | E12: Created By | F12: Creation Date | G12: Document Status | H12: Approved By | J12: Approval Date
D13: DEV | G13: Initial
D14: QAS | G14: Initial
D15: PRD | G15: Initial
B17: Unit Testing Document
B19: ID | C19: Scenario | D19: Test Case | E19: Responsible | F19: Expected Results | G19: Execution Results | H19: Successfull (Yes/No) | I19: Date | J19: Comments | K19: Evidence Link
B20: {=_xlfn._xlws.FILTER('EXPLORE - Test Scenarios'!B:F, LOWER('EXPLORE - Test Scenarios'!G:G="yes"))} -> #VALUE!

Sheet Functional Testing Results
B1: Unit Testing Document: Testing Inventory
B2: Document Roles
C4: Role Name | D4: Consultant Name | E4: Create / Review
C5: SAP SuccessFactors Platform | D5: =IF(VLOOKUP(C5,Overview!$E$23:$J$42,5,FALSE)="","",VLOOKUP(C5,Overview!$E$23:$J$42,5,FALSE)) | E5: Create
C6: SAP Integration Developer | D6: =IF(VLOOKUP(C6,Overview!$E$23:$J$42,5,FALSE)="","",VLOOKUP(C6,Overview!$E$23:$J$42,5,FALSE)) | E6: Review
C7: SAP Solution Architect | D7: =IF(VLOOKUP(C7,Overview!$E$23:$J$42,5,FALSE)="","",VLOOKUP(C7,Overview!$E$23:$J$42,5,FALSE)) | E7: Review
C8: SAP Integration Architect | D8: =IF(VLOOKUP(C8,Overview!$E$23:$J$42,5,FALSE)="","",VLOOKUP(C8,Overview!$E$23:$J$42,5,FALSE)) | E8: Review | I8: *Do not edit
B10: Document Status
C12: Description | D12: Stage | E12: Created By | F12: Creation Date | G12: Document Status | H12: Approved By | J12: Approval Date
D13: DEV | G13: Initial
D14: QAS | G14: Initial
D15: PRD | G15: Initial
B17: Unit Testing Document
B19: ID | C19: Scenario | D19: Test Case | E19: Responsible | F19: Expected Results | G19: Execution Results | H19: Successfull (Yes/No) | I19: Date | J19: Comments | K19: Evidence Link
B20: {=_xlfn._xlws.FILTER('EXPLORE - Test Scenarios'!B:F, LOWER('EXPLORE - Test Scenarios'!H:H="yes"))} -> #VALUE!

Sheet UAT Testing Results
B1: Unit Testing Document: Testing Inventory
B2: Document Roles
C4: Role Name | D4: Consultant Name | E4: Create / Review
C5: SAP SuccessFactors Platform | D5: =IF(VLOOKUP(C5,Overview!$E$23:$J$42,5,FALSE)="","",VLOOKUP(C5,Overview!$E$23:$J$42,5,FALSE)) | E5: Create
C6: SAP Integration Developer | D6: =IF(VLOOKUP(C6,Overview!$E$23:$J$42,5,FALSE)="","",VLOOKUP(C6,Overview!$E$23:$J$42,5,FALSE)) | E6: Review
C7: SAP Solution Architect | D7: =IF(VLOOKUP(C7,Overview!$E$23:$J$42,5,FALSE)="","",VLOOKUP(C7,Overview!$E$23:$J$42,5,FALSE)) | E7: Review
C8: SAP Integration Architect | D8: =IF(VLOOKUP(C8,Overview!$E$23:$J$42,5,FALSE)="","",VLOOKUP(C8,Overview!$E$23:$J$42,5,FALSE)) | E8: Review | I8: *Do not edit
B10: Document Status
C12: Description | D12: Stage | E12: Created By | F12: Creation Date | G12: Document Status | H12: Approved By | J12: Approval Date
D13: DEV | G13: Initial
D14: QAS | G14: Initial
D15: PRD | G15: Initial
B17: Unit Testing Document
B19: ID | C19: Scenario | D19: Test Case | E19: Responsible | F19: Expected Results | G19: Execution Results | H19: Successfull (Yes/No) | I19: Date | J19: Comments | K19: Evidence Link
B20: {=_xlfn._xlws.FILTER('EXPLORE - Test Scenarios'!B:F, LOWER('EXPLORE - Test Scenarios'!I:I="yes"))} -> #VALUE!

Sheet CLOUD CARE
B1: Cloud Care: Changes and Tickets
B5: Cloud Care Changes
B7: DATE | C7: DESCRIPTION | M7: TYPE | N7: TICKET | O7: DEVELOPER
M12: ABAP/CPI

Sheet $DATA
A1: Approval Status | C1: Error Status
A2: Approved | C2: Fixed
A3: In Progress | C3: Functional Analysis
A4: Draft | C4: Technical Analysis
A5: Initial | C5: Technical Testing
C6: Functional Testing
